Workbook

Sheet ⚙️ Settings
A1: ⚙️ SYSTEM SETTINGS & LOOKUP TABLES — ARAB UNITY SCHOOL | AY 2025-26
A3: Status | C3: Priority | E3: Category | G3: Location | I3: Term | K3: Assigned To | M3: ⚙️ KPI Target | N3: Value
A4: ⏳ Pending | C4: 🔴 Critical | E4: Electrical | G4: Main Building | I4: Term 1 | K4: Maintenance Team | M4: Completion Rate Target | N4: 0.75
A5: 🔄 In Progress | C5: 🟠 High | E5: Plumbing | G5: Block A – Boys | I5: Term 2 | K5: Cleaning Crew | M5: Max Overdue Tasks | N5: 5
A6: ⏸ On Hold | C6: 🟡 Medium | E6: Civil / Building | G6: Block B – Girls | I6: Term 3 | K6: IT Team | M6: Max Critical Pending | N6: 2
A7: ✅ Completed | C7: 🟢 Low | E7: HVAC / AC | G7: Primary Section | I7: Summer | K7: Electrical Team | M7: Annual Budget Threshold AED | N7: 500000
A8: ❌ Cancelled | E8: Painting | G8: Taher Hall | K8: HVAC Contractor | M8: On-Time Rate Target | N8: 0.85
E9: Carpentry | G9: Admin Office | K9: Safety Officer
E10: Cleaning | G10: Gym / Sports Hall | K10: Pool Contractor
E11: IT / AV Equipment | G11: Swimming Pool | K11: External Vendor
E12: Safety & Security | G12: Canteen / Kitchen | K12: In-House
E13: Landscaping | G13: Parking
E14: Furniture | G14: Outdoor / Playground
E15: Pest Control | G15: Library
E16: Other | G16: Science Lab
G17: Art Room
G18: IT Lab
G19: Auditorium
G20: Toilets
G21: Storage Room
G22: Other

Sheet 📋 Task Tracker
A1: 🏫 ARAB UNITY SCHOOL — MAINTENANCE MANAGEMENT SYSTEM | AY 2025-26 (ANNUAL)
A3: # | B3: Task ID | C3: Task Title | D3: Category | E3: Location | F3: Term | G3: Priority | H3: Status | I3: Assigned To | J3: Reported By | K3: Date Reported | L3: Due Date | M3: Date Completed | N3: Days to Close | O3: Overdue? | P3: Cost (AED) | Q3: Vendor | R3: % Progress | S3: Health Score | T3: Notes | U3: 📎 Attachment / File Link
A4: 1 | B4: MNT-001 | C4: Fix broken ceiling tiles – Classroom B3 | D4: Civil / Building | E4: Block A – Boys | F4: Term 1 | G4: 🟠 High | H4: ✅ Completed | I4: Maintenance Team | J4: Principal | K4: 15/09/2025 | L4: 25/09/2025 | M4: 24/09/2025 | N4: =IF(M4<>"",IF(AND(ISNUMBER(DATEVALUE(M4)),ISNUMBER(DATEVALUE(K4))),DATEVALUE(M4)-DATEVALUE(K4),""),IF(ISNUMBER(DATEVALUE(K4)),TODAY()-DATEVALUE(K4),"")) | O4: =IF(AND(H4<>"✅ Completed",H4<>"❌ Cancelled",ISNUMBER(DATEVALUE(L4)),TODAY()>DATEVALUE(L4)),"🚨 OVERDUE","") -> #VALUE! | P4: 1200 | Q4: Al Noor Contractors | R4: 100% | S4: =IF(H4="✅ Completed",100,IF(H4="❌ Cancelled",0,IF(AND(H4="⏳ Pending",G4="🔴 Critical"),10,IF(AND(H4="⏳ Pending",G4="🟠 High"),30,IF(H4="🔄 In Progress",60,IF(H4="⏸ On Hold",40,50)))))) -> 100 | T4: Completed on time
A5: 2 | B5: MNT-002 | C5: AC unit not cooling – Science Lab | D5: HVAC / AC | E5: Science Lab | F5: Term 1 | G5: 🔴 Critical | H5: ✅ Completed | I5: HVAC Contractor | J5: Vice Principal | K5: 20/09/2025 | L5: 22/09/2025 | M5: 22/09/2025 | N5: =IF(M5<>"",IF(AND(ISNUMBER(DATEVALUE(M5)),ISNUMBER(DATEVALUE(K5))),DATEVALUE(M5)-DATEVALUE(K5),""),IF(ISNUMBER(DATEVALUE(K5)),TODAY()-DATEVALUE(K5),"")) | O5: =IF(AND(H5<>"✅ Completed",H5<>"❌ Cancelled",ISNUMBER(DATEVALUE(L5)),TODAY()>DATEVALUE(L5)),"🚨 OVERDUE","") -> #VALUE! | P5: 800 | Q5: Cool Air Services | R5: 100% | S5: =IF(H5="✅ Completed",100,IF(H5="❌ Cancelled",0,IF(AND(H5="⏳ Pending",G5="🔴 Critical"),10,IF(AND(H5="⏳ Pending",G5="🟠 High"),30,IF(H5="🔄 In Progress",60,IF(H5="⏸ On Hold",40,50)))))) -> 100 | T5: Emergency fix
A6: 3 | B6: MNT-003 | C6: Repaint exterior wall – Main entrance | D6: Painting | E6: Main Building | F6: Term 1 | G6: 🟡 Medium | H6: ✅ Completed | I6: External Vendor | J6: Head of Operations | K6: 01/10/2025 | L6: 20/10/2025 | M6: 18/10/2025 | N6: =IF(M6<>"",IF(AND(ISNUMBER(DATEVALUE(M6)),ISNUMBER(DATEVALUE(K6))),DATEVALUE(M6)-DATEVALUE(K6),""),IF(ISNUMBER(DATEVALUE(K6)),TODAY()-DATEVALUE(K6),"")) | O6: =IF(AND(H6<>"✅ Completed",H6<>"❌ Cancelled",ISNUMBER(DATEVALUE(L6)),TODAY()>DATEVALUE(L6)),"🚨 OVERDUE","") -> #VALUE! | P6: 3500 | Q6: BrightPaint LLC | R6: 100% | S6: =IF(H6="✅ Completed",100,IF(H6="❌ Cancelled",0,IF(AND(H6="⏳ Pending",G6="🔴 Critical"),10,IF(AND(H6="⏳ Pending",G6="🟠 High"),30,IF(H6="🔄 In Progress",60,IF(H6="⏸ On Hold",40,50)))))) -> 100 | T6: Completed before inspection
A7: 4 | B7: MNT-004 | C7: Replace faulty electrical sockets – IT Lab | D7: Electrical | E7: IT Lab | F7: Term 1 | G7: 🟠 High | H7: ✅ Completed | I7: Electrical Team | J7: Facility Officer | K7: 05/10/2025 | L7: 10/10/2025 | M7: 09/10/2025 | N7: =IF(M7<>"",IF(AND(ISNUMBER(DATEVALUE(M7)),ISNUMBER(DATEVALUE(K7))),DATEVALUE(M7)-DATEVALUE(K7),""),IF(ISNUMBER(DATEVALUE(K7)),TODAY()-DATEVALUE(K7),"")) -> 123 | O7: =IF(AND(H7<>"✅ Completed",H7<>"❌ Cancelled",ISNUMBER(DATEVALUE(L7)),TODAY()>DATEVALUE(L7)),"🚨 OVERDUE","") | P7: 450 | Q7: Spark Electric Co. | R7: 100% | S7: =IF(H7="✅ Completed",100,IF(H7="❌ Cancelled",0,IF(AND(H7="⏳ Pending",G7="🔴 Critical"),10,IF(AND(H7="⏳ Pending",G7="🟠 High"),30,IF(H7="🔄 In Progress",60,IF(H7="⏸ On Hold",40,50)))))) -> 100 | T7: 6 sockets replaced
A8: 5 | B8: MNT-005 | C8: Unclog drain – Boys toilets Block A | D8: Plumbing | E8: Toilets | F8: Term 1 | G8: 🔴 Critical | H8: ✅ Completed | I8: Maintenance Team | J8: Principal | K8: 12/10/2025 | L8: 13/10/2025 | M8: 13/10/2025 | N8: =IF(M8<>"",IF(AND(ISNUMBER(DATEVALUE(M8)),ISNUMBER(DATEVALUE(K8))),DATEVALUE(M8)-DATEVALUE(K8),""),IF(ISNUMBER(DATEVALUE(K8)),TODAY()-DATEVALUE(K8),"")) | O8: =IF(AND(H8<>"✅ Completed",H8<>"❌ Cancelled",ISNUMBER(DATEVALUE(L8)),TODAY()>DATEVALUE(L8)),"🚨 OVERDUE","") -> #VALUE! | P8: 200 | Q8: In-House | R8: 100% | S8: =IF(H8="✅ Completed",100,IF(H8="❌ Cancelled",0,IF(AND(H8="⏳ Pending",G8="🔴 Critical"),10,IF(AND(H8="⏳ Pending",G8="🟠 High"),30,IF(H8="🔄 In Progress",60,IF(H8="⏸ On Hold",40,50)))))) -> 100 | T8: Same day fix
A9: 6 | B9: MNT-006 | C9: Install new projector – Auditorium | D9: IT / AV Equipment | E9: Auditorium | F9: Term 1 | G9: 🟡 Medium | H9: ✅ Completed | I9: IT Team | J9: Vice Principal | K9: 15/10/2025 | L9: 30/10/2025 | M9: 28/10/2025 | N9: =IF(M9<>"",IF(AND(ISNUMBER(DATEVALUE(M9)),ISNUMBER(DATEVALUE(K9))),DATEVALUE(M9)-DATEVALUE(K9),""),IF(ISNUMBER(DATEVALUE(K9)),TODAY()-DATEVALUE(K9),"")) | O9: =IF(AND(H9<>"✅ Completed",H9<>"❌ Cancelled",ISNUMBER(DATEVALUE(L9)),TODAY()>DATEVALUE(L9)),"🚨 OVERDUE","") -> #VALUE! | P9: 5800 | Q9: TechVision UAE | R9: 100% | S9: =IF(H9="✅ Completed",100,IF(H9="❌ Cancelled",0,IF(AND(H9="⏳ Pending",G9="🔴 Critical"),10,IF(AND(H9="⏳ Pending",G9="🟠 High"),30,IF(H9="🔄 In Progress",60,IF(H9="⏸ On Hold",40,50)))))) -> 100 | T9: Installed & tested
A10: 7 | B10: MNT-007 | C10: Replace broken fence panel – Playground | D10: Civil / Building | E10: Outdoor / Playground | F10: Term 1 | G10: 🟠 High | H10: ✅ Completed | I10: External Vendor | J10: Head of Operations | K10: 20/10/2025 | L10: 01/11/2025 | M10: 30/10/2025 | N10: =IF(M10<>"",IF(AND(ISNUMBER(DATEVALUE(M10)),ISNUMBER(DATEVALUE(K10))),DATEVALUE(M10)-DATEVALUE(K10),""),IF(ISNUMBER(DATEVALUE(K10)),TODAY()-DATEVALUE(K10),"")) | O10: =IF(AND(H10<>"✅ Completed",H10<>"❌ Cancelled",ISNUMBER(DATEVALUE(L10)),TODAY()>DATEVALUE(L10)),"🚨 OVERDUE","") | P10: 950 | Q10: SafeBuild Contractors | R10: 100% | S10: =IF(H10="✅ Completed",100,IF(H10="❌ Cancelled",0,IF(AND(H10="⏳ Pending",G10="🔴 Critical"),10,IF(AND(H10="⏳ Pending",G10="🟠 High"),30,IF(H10="🔄 In Progress",60,IF(H10="⏸ On Hold",40,50)))))) -> 100 | T10: Safety hazard resolved
A11: 8 | B11: MNT-008 | C11: CCTV camera replacement – Block B | D11: Safety & Security | E11: Block B – Girls | F11: Term 1 | G11: 🟠 High | H11: ✅ Completed | I11: IT Team | J11: Facility Officer | K11: 25/10/2025 | L11: 10/11/2025 | M11: 08/11/2025 | N11: =IF(M11<>"",IF(AND(ISNUMBER(DATEVALUE(M11)),ISNUMBER(DATEVALUE(K11))),DATEVALUE(M11)-DATEVALUE(K11),""),IF(ISNUMBER(DATEVALUE(K11)),TODAY()-DATEVALUE(K11),"")) | O11: =IF(AND(H11<>"✅ Completed",H11<>"❌ Cancelled",ISNUMBER(DATEVALUE(L11)),TODAY()>DATEVALUE(L11)),"🚨 OVERDUE","") | P11: 2100 | Q11: SecureVision Systems | R11: 100% | S11: =IF(H11="✅ Completed",100,IF(H11="❌ Cancelled",0,IF(AND(H11="⏳ Pending",G11="🔴 Critical"),10,IF(AND(H11="⏳ Pending",G11="🟠 High"),30,IF(H11="🔄 In Progress",60,IF(H11="⏸ On Hold",40,50)))))) -> 100 | T11: 5 cameras replaced
A12: 9 | B12: MNT-009 | C12: Pest control – Canteen & Storage | D12: Pest Control | E12: Canteen / Kitchen | F12: Term 1 | G12: 🟡 Medium | H12: ✅ Completed | I12: External Vendor | J12: Principal | K12: 01/11/2025 | L12: 05/11/2025 | M12: 04/11/2025 | N12: =IF(M12<>"",IF(AND(ISNUMBER(DATEVALUE(M12)),ISNUMBER(DATEVALUE(K12))),DATEVALUE(M12)-DATEVALUE(K12),""),IF(ISNUMBER(DATEVALUE(K12)),TODAY()-DATEVALUE(K12),"")) -> 90 | O12: =IF(AND(H12<>"✅ Completed",H12<>"❌ Cancelled",ISNUMBER(DATEVALUE(L12)),TODAY()>DATEVALUE(L12)),"🚨 OVERDUE","") | P12: 600 | Q12: PestFree UAE | R12: 100% | S12: =IF(H12="✅ Completed",100,IF(H12="❌ Cancelled",0,IF(AND(H12="⏳ Pending",G12="🔴 Critical"),10,IF(AND(H12="⏳ Pending",G12="🟠 High"),30,IF(H12="🔄 In Progress",60,IF(H12="⏸ On Hold",40,50)))))) -> 100 | T12: Monthly treatment
A13: 10 | B13: MNT-010 | C13: Repair water fountain – Main lobby | D13: Plumbing | E13: Main Building | F13: Term 1 | G13: 🟢 Low | H13: ✅ Completed | I13: Maintenance Team | J13: Vice Principal | K13: 10/11/2025 | L13: 30/11/2025 | M13: 25/11/2025 | N13: =IF(M13<>"",IF(AND(ISNUMBER(DATEVALUE(M13)),ISNUMBER(DATEVALUE(K13))),DATEVALUE(M13)-DATEVALUE(K13),""),IF(ISNUMBER(DATEVALUE(K13)),TODAY()-DATEVALUE(K13),"")) | O13: =IF(AND(H13<>"✅ Completed",H13<>"❌ Cancelled",ISNUMBER(DATEVALUE(L13)),TODAY()>DATEVALUE(L13)),"🚨 OVERDUE","") -> #VALUE! | P13: 300 | Q13: In-House | R13: 100% | S13: =IF(H13="✅ Completed",100,IF(H13="❌ Cancelled",0,IF(AND(H13="⏳ Pending",G13="🔴 Critical"),10,IF(AND(H13="⏳ Pending",G13="🟠 High"),30,IF(H13="🔄 In Progress",60,IF(H13="⏸ On Hold",40,50)))))) -> 100 | T13: Spare part arrived late
A14: 11 | B14: MNT-011 | C14: Library roof leak – emergency patch | D14: Civil / Building | E14: Library | F14: Term 1 | G14: 🔴 Critical | H14: ✅ Completed | I14: External Vendor | J14: Head of Operations | K14: 15/11/2025 | L14: 17/11/2025 | M14: 17/11/2025 | N14: =IF(M14<>"",IF(AND(ISNUMBER(DATEVALUE(M14)),ISNUMBER(DATEVALUE(K14))),DATEVALUE(M14)-DATEVALUE(K14),""),IF(ISNUMBER(DATEVALUE(K14)),TODAY()-DATEVALUE(K14),"")) | O14: =IF(AND(H14<>"✅ Completed",H14<>"❌ Cancelled",ISNUMBER(DATEVALUE(L14)),TODAY()>DATEVALUE(L14)),"🚨 OVERDUE","") -> #VALUE! | P14: 1800 | Q14: Al Noor Contractors | R14: 100% | S14: =IF(H14="✅ Completed",100,IF(H14="❌ Cancelled",0,IF(AND(H14="⏳ Pending",G14="🔴 Critical"),10,IF(AND(H14="⏳ Pending",G14="🟠 High"),30,IF(H14="🔄 In Progress",60,IF(H14="⏸ On Hold",40,50)))))) -> 100 | T14: Full repair planned T3
A15: 12 | B15: MNT-012 | C15: Generator annual service | D15: Electrical | E15: Main Building | F15: Term 1 | G15: 🟠 High | H15: ✅ Completed | I15: Electrical Team | J15: Facility Officer | K15: 20/11/2025 | L15: 30/11/2025 | M15: 28/11/2025 | N15: =IF(M15<>"",IF(AND(ISNUMBER(DATEVALUE(M15)),ISNUMBER(DATEVALUE(K15))),DATEVALUE(M15)-DATEVALUE(K15),""),IF(ISNUMBER(DATEVALUE(K15)),TODAY()-DATEVALUE(K15),"")) | O15: =IF(AND(H15<>"✅ Completed",H15<>"❌ Cancelled",ISNUMBER(DATEVALUE(L15)),TODAY()>DATEVALUE(L15)),"🚨 OVERDUE","") -> #VALUE! | P15: 2500 | Q15: Spark Electric Co. | R15: 100% | S15: =IF(H15="✅ Completed",100,IF(H15="❌ Cancelled",0,IF(AND(H15="⏳ Pending",G15="🔴 Critical"),10,IF(AND(H15="⏳ Pending",G15="🟠 High"),30,IF(H15="🔄 In Progress",60,IF(H15="⏸ On Hold",40,50)))))) -> 100 | T15: Certificate obtained
... A23: 20 | B23: MNT-020 | C23: Canteen exhaust fan replacement | D23: HVAC / AC | E23: Canteen / Kitchen | F23: Term 2 | G23: 🟠 High | H23: ✅ Completed | I23: HVAC Contractor | J23: Head of Operations | K23: 05/02/2026 | L23: 15/02/2026 | M23: 14/02/2026 | N23: =IF(M23<>"",IF(AND(ISNUMBER(DATEVALUE(M23)),ISNUMBER(DATEVALUE(K23))),DATEVALUE(M23)-DATEVALUE(K23),""),IF(ISNUMBER(DATEVALUE(K23)),TODAY()-DATEVALUE(K23),"")) | O23: =IF(AND(H23<>"✅ Completed",H23<>"❌ Cancelled",ISNUMBER(DATEVALUE(L23)),TODAY()>DATEVALUE(L23)),"🚨 OVERDUE","") -> #VALUE! | P23: 750 | Q23: Cool Air Services | R23: 100% | S23: =IF(H23="✅ Completed",100,IF(H23="❌ Cancelled",0,IF(AND(H23="⏳ Pending",G23="🔴 Critical"),10,IF(AND(H23="⏳ Pending",G23="🟠 High"),30,IF(H23="🔄 In Progress",60,IF(H23="⏸ On Hold",40,50)))))) -> 100 | T23: Old fan replaced
A24: 21 | B24: MNT-021 | C24: Fix broken ceiling tiles – Classroom B3 | D24: Civil / Building | E24: Block A – Boys | F24: Term 3 | G24: 🟠 High | H24: 🔄 In Progress | I24: Maintenance Team | J24: Principal | K24: 01/03/2026 | L24: 10/03/2026 | N24: =IF(M24<>"",IF(AND(ISNUMBER(DATEVALUE(M24)),ISNUMBER(DATEVALUE(K24))),DATEVALUE(M24)-DATEVALUE(K24),""),IF(ISNUMBER(DATEVALUE(K24)),TODAY()-DATEVALUE(K24),"")) -> 66 | O24: =IF(AND(H24<>"✅ Completed",H24<>"❌ Cancelled",ISNUMBER(DATEVALUE(L24)),TODAY()>DATEVALUE(L24)),"🚨 OVERDUE","") | P24: 1200 | Q24: Al Noor Contractors | R24: 40% | S24: =IF(H24="✅ Completed",100,IF(H24="❌ Cancelled",0,IF(AND(H24="⏳ Pending",G24="🔴 Critical"),10,IF(AND(H24="⏳ Pending",G24="🟠 High"),30,IF(H24="🔄 In Progress",60,IF(H24="⏸ On Hold",40,50)))))) -> 60 | T24: 3 tiles cracked
A25: 22 | B25: MNT-022 | C25: AC unit not cooling – Science Lab | D25: HVAC / AC | E25: Science Lab | F25: Term 3 | G25: 🔴 Critical | H25: ⏳ Pending | I25: HVAC Contractor | J25: Vice Principal | K25: 03/03/2026 | L25: 05/03/2026 | N25: =IF(M25<>"",IF(AND(ISNUMBER(DATEVALUE(M25)),ISNUMBER(DATEVALUE(K25))),DATEVALUE(M25)-DATEVALUE(K25),""),IF(ISNUMBER(DATEVALUE(K25)),TODAY()-DATEVALUE(K25),"")) -> 7 | O25: =IF(AND(H25<>"✅ Completed",H25<>"❌ Cancelled",ISNUMBER(DATEVALUE(L25)),TODAY()>DATEVALUE(L25)),"🚨 OVERDUE","") | P25: 800 | Q25: Cool Air Services | R25: 0% | S25: =IF(H25="✅ Completed",100,IF(H25="❌ Cancelled",0,IF(AND(H25="⏳ Pending",G25="🔴 Critical"),10,IF(AND(H25="⏳ Pending",G25="🟠 High"),30,IF(H25="🔄 In Progress",60,IF(H25="⏸ On Hold",40,50)))))) -> 10 | T25: Class relocated
A26: 23 | B26: MNT-023 | C26: Repaint exterior – Admin entrance | D26: Painting | E26: Admin Office | F26: Term 3 | G26: 🟡 Medium | H26: ⏳ Pending | I26: External Vendor | J26: Head of Operations | K26: 05/03/2026 | L26: 25/03/2026 | N26: =IF(M26<>"",IF(AND(ISNUMBER(DATEVALUE(M26)),ISNUMBER(DATEVALUE(K26))),DATEVALUE(M26)-DATEVALUE(K26),""),IF(ISNUMBER(DATEVALUE(K26)),TODAY()-DATEVALUE(K26),"")) -> -54 | O26: =IF(AND(H26<>"✅ Completed",H26<>"❌ Cancelled",ISNUMBER(DATEVALUE(L26)),TODAY()>DATEVALUE(L26)),"🚨 OVERDUE","") -> #VALUE! | P26: 3500 | Q26: BrightPaint LLC | R26: 0% | S26: =IF(H26="✅ Completed",100,IF(H26="❌ Cancelled",0,IF(AND(H26="⏳ Pending",G26="🔴 Critical"),10,IF(AND(H26="⏳ Pending",G26="🟠 High"),30,IF(H26="🔄 In Progress",60,IF(H26="⏸ On Hold",40,50)))))) -> 50 | T26: Spring break scheduled
A27: 24 | B27: MNT-024 | C27: Replace faulty sockets – Block B | D27: Electrical | E27: Block B – Girls | F27: Term 3 | G27: 🟠 High | H27: ⏸ On Hold | I27: Electrical Team | J27: Facility Officer | K27: 07/03/2026 | L27: 18/03/2026 | N27: =IF(M27<>"",IF(AND(ISNUMBER(DATEVALUE(M27)),ISNUMBER(DATEVALUE(K27))),DATEVALUE(M27)-DATEVALUE(K27),""),IF(ISNUMBER(DATEVALUE(K27)),TODAY()-DATEVALUE(K27),"")) -> -115 | O27: =IF(AND(H27<>"✅ Completed",H27<>"❌ Cancelled",ISNUMBER(DATEVALUE(L27)),TODAY()>DATEVALUE(L27)),"🚨 OVERDUE","") -> #VALUE! | P27: 450 | Q27: Spark Electric Co. | R27: 10% | S27: =IF(H27="✅ Completed",100,IF(H27="❌ Cancelled",0,IF(AND(H27="⏳ Pending",G27="🔴 Critical"),10,IF(AND(H27="⏳ Pending",G27="🟠 High"),30,IF(H27="🔄 In Progress",60,IF(H27="⏸ On Hold",40,50)))))) -> 40 | T27: Awaiting parts
A28: 25 | B28: MNT-025 | C28: CCTV camera replacement – Block C | D28: Safety & Security | E28: Block A – Boys | F28: Term 3 | G28: 🟠 High | H28: 🔄 In Progress | I28: IT Team | J28: Facility Officer | K28: 28/02/2026 | L28: 14/03/2026 | N28: =IF(M28<>"",IF(AND(ISNUMBER(DATEVALUE(M28)),ISNUMBER(DATEVALUE(K28))),DATEVALUE(M28)-DATEVALUE(K28),""),IF(ISNUMBER(DATEVALUE(K28)),TODAY()-DATEVALUE(K28),"")) | O28: =IF(AND(H28<>"✅ Completed",H28<>"❌ Cancelled",ISNUMBER(DATEVALUE(L28)),TODAY()>DATEVALUE(L28)),"🚨 OVERDUE","") -> #VALUE! | P28: 2100 | Q28: SecureVision Systems | R28: 60% | S28: =IF(H28="✅ Completed",100,IF(H28="❌ Cancelled",0,IF(AND(H28="⏳ Pending",G28="🔴 Critical"),10,IF(AND(H28="⏳ Pending",G28="🟠 High"),30,IF(H28="🔄 In Progress",60,IF(H28="⏸ On Hold",40,50)))))) -> 60 | T28: 3 of 5 installed
A29: 26 | B29: MNT-026 | C29: Pest control – Canteen | D29: Pest Control | E29: Canteen / Kitchen | F29: Term 3 | G29: 🟡 Medium | H29: ⏳ Pending | I29: External Vendor | J29: Principal | K29: 05/03/2026 | L29: 08/03/2026 | N29: =IF(M29<>"",IF(AND(ISNUMBER(DATEVALUE(M29)),ISNUMBER(DATEVALUE(K29))),DATEVALUE(M29)-DATEVALUE(K29),""),IF(ISNUMBER(DATEVALUE(K29)),TODAY()-DATEVALUE(K29),"")) -> -54 | O29: =IF(AND(H29<>"✅ Completed",H29<>"❌ Cancelled",ISNUMBER(DATEVALUE(L29)),TODAY()>DATEVALUE(L29)),"🚨 OVERDUE","") | P29: 600 | Q29: PestFree UAE | R29: 0% | S29: =IF(H29="✅ Completed",100,IF(H29="❌ Cancelled",0,IF(AND(H29="⏳ Pending",G29="🔴 Critical"),10,IF(AND(H29="⏳ Pending",G29="🟠 High"),30,IF(H29="🔄 In Progress",60,IF(H29="⏸ On Hold",40,50)))))) -> 50 | T29: Monthly treatment
A30: 27 | B30: MNT-027 | C30: Library full roof repair | D30: Civil / Building | E30: Library | F30: Term 3 | G30: 🔴 Critical | H30: ⏳ Pending | I30: External Vendor | J30: Head of Operations | K30: 06/03/2026 | L30: 30/03/2026 | N30: =IF(M30<>"",IF(AND(ISNUMBER(DATEVALUE(M30)),ISNUMBER(DATEVALUE(K30))),DATEVALUE(M30)-DATEVALUE(K30),""),IF(ISNUMBER(DATEVALUE(K30)),TODAY()-DATEVALUE(K30),"")) -> -85 | O30: =IF(AND(H30<>"✅ Completed",H30<>"❌ Cancelled",ISNUMBER(DATEVALUE(L30)),TODAY()>DATEVALUE(L30)),"🚨 OVERDUE","") -> #VALUE! | P30: 8500 | Q30: Al Noor Contractors | R30: 0% | S30: =IF(H30="✅ Completed",100,IF(H30="❌ Cancelled",0,IF(AND(H30="⏳ Pending",G30="🔴 Critical"),10,IF(AND(H30="⏳ Pending",G30="🟠 High"),30,IF(H30="🔄 In Progress",60,IF(H30="⏸ On Hold",40,50)))))) -> 10 | T30: Permanent fix for T1 patch
A31: 28 | B31: MNT-028 | C31: Gym wall painting | D31: Painting | E31: Gym / Sports Hall | F31: Term 3 | G31: 🟢 Low | H31: ⏳ Pending | I31: External Vendor | J31: Vice Principal | K31: 08/03/2026 | L31: 30/03/2026 | N31: =IF(M31<>"",IF(AND(ISNUMBER(DATEVALUE(M31)),ISNUMBER(DATEVALUE(K31))),DATEVALUE(M31)-DATEVALUE(K31),""),IF(ISNUMBER(DATEVALUE(K31)),TODAY()-DATEVALUE(K31),"")) -> -146 | O31: =IF(AND(H31<>"✅ Completed",H31<>"❌ Cancelled",ISNUMBER(DATEVALUE(L31)),TODAY()>DATEVALUE(L31)),"🚨 OVERDUE","") -> #VALUE! | P31: 1800 | Q31: BrightPaint LLC | R31: 0% | S31: =IF(H31="✅ Completed",100,IF(H31="❌ Cancelled",0,IF(AND(H31="⏳ Pending",G31="🔴 Critical"),10,IF(AND(H31="⏳ Pending",G31="🟠 High"),30,IF(H31="🔄 In Progress",60,IF(H31="⏸ On Hold",40,50)))))) -> 50
A32: 29 | B32: MNT-029 | C32: IT lab server room AC | D32: HVAC / AC | E32: IT Lab | F32: Term 3 | G32: 🔴 Critical | H32: 🔄 In Progress | I32: HVAC Contractor | J32: Facility Officer | K32: 02/03/2026 | L32: 09/03/2026 | N32: =IF(M32<>"",IF(AND(ISNUMBER(DATEVALUE(M32)),ISNUMBER(DATEVALUE(K32))),DATEVALUE(M32)-DATEVALUE(K32),""),IF(ISNUMBER(DATEVALUE(K32)),TODAY()-DATEVALUE(K32),"")) -> 35 | O32: =IF(AND(H32<>"✅ Completed",H32<>"❌ Cancelled",ISNUMBER(DATEVALUE(L32)),TODAY()>DATEVALUE(L32)),"🚨 OVERDUE","") | P32: 1900 | Q32: Cool Air Services | R32: 50% | S32: =IF(H32="✅ Completed",100,IF(H32="❌ Cancelled",0,IF(AND(H32="⏳ Pending",G32="🔴 Critical"),10,IF(AND(H32="⏳ Pending",G32="🟠 High"),30,IF(H32="🔄 In Progress",60,IF(H32="⏸ On Hold",40,50)))))) -> 60 | T32: Server overheating risk
A33: 30 | B33: MNT-030 | C33: Outdoor lighting – playground | D33: Electrical | E33: Outdoor / Playground | F33: Term 3 | G33: 🟡 Medium | H33: ⏳ Pending | I33: Electrical Team | J33: Principal | K33: 09/03/2026 | L33: 20/03/2026 | N33: =IF(M33<>"",IF(AND(ISNUMBER(DATEVALUE(M33)),ISNUMBER(DATEVALUE(K33))),DATEVALUE(M33)-DATEVALUE(K33),""),IF(ISNUMBER(DATEVALUE(K33)),TODAY()-DATEVALUE(K33),"")) -> -177 | O33: =IF(AND(H33<>"✅ Completed",H33<>"❌ Cancelled",ISNUMBER(DATEVALUE(L33)),TODAY()>DATEVALUE(L33)),"🚨 OVERDUE","") -> #VALUE! | P33: 2200 | Q33: Spark Electric Co. | R33: 0% | S33: =IF(H33="✅ Completed",100,IF(H33="❌ Cancelled",0,IF(AND(H33="⏳ Pending",G33="🔴 Critical"),10,IF(AND(H33="⏳ Pending",G33="🟠 High"),30,IF(H33="🔄 In Progress",60,IF(H33="⏸ On Hold",40,50)))))) -> 50 | T33: Safety upgrade
A34: 31 | B34: MNT-031
A35: 32 | B35: MNT-032
A36: 33 | B36: MNT-033
A37: 34 | B37: MNT-034
A38: 35 | B38: MNT-035
A39: 36 | B39: MNT-036
A40: 37 | B40: MNT-037
A41: 38 | B41: MNT-038
A42: 39 | B42: MNT-039
A43: 40 | B43: MNT-040
A44: 41 | B44: MNT-041
A45: 42 | B45: MNT-042
... A203: 200 | B203: MNT-200
A205: 💰 ANNUAL TOTAL COST (All Tasks • AY 2025-26) | P205: =SUM(P4:P203) -> 61750

Sheet 📊 Analytics Dashboard
B1: 📊 ANNUAL ANALYTICS DASHBOARD — ARAB UNITY SCHOOL | AY 2025-26
B4: ⚡ ANNUAL KEY PERFORMANCE INDICATORS — AY 2025-26
B5: 📋 Total Tasks (Annual) | D5: ✅ Completed | F5: 🔄 In Progress | H5: ⏳ Pending | J5: 🚨 Overdue | L5: ⏸ On Hold | N5: 🔴 Critical Pending
B6: =COUNTA('📋 Task Tracker'!C4:C203)-COUNTBLANK('📋 Task Tracker'!C4:C203) -> -140 | D6: =COUNTIF('📋 Task Tracker'!H4:H203,"✅ Completed") -> 20 | F6: =COUNTIF('📋 Task Tracker'!H4:H203,"🔄 In Progress") -> 3 | H6: =COUNTIF('📋 Task Tracker'!H4:H203,"⏳ Pending") -> 6 | J6: =COUNTIF('📋 Task Tracker'!O4:O203,"🚨 OVERDUE") -> 0 | L6: =COUNTIF('📋 Task Tracker'!H4:H203,"⏸ On Hold") -> 1 | N6: =COUNTIFS('📋 Task Tracker'!G4:G203,"🔴 Critical",'📋 Task Tracker'!H4:H203,"⏳ Pending") -> 2
B9: 📌 Task Status Breakdown | J9: ⚡ Priority Distribution
B10: ⏳ Pending | F10: =COUNTIF('📋 Task Tracker'!H4:H203,"⏳ Pending") -> 6 | J10: 🔴 Critical | N10: =COUNTIF('📋 Task Tracker'!G4:G203,"🔴 Critical") -> 8
B11: 🔄 In Progress | F11: =COUNTIF('📋 Task Tracker'!H4:H203,"🔄 In Progress") -> 3 | J11: 🟠 High | N11: =COUNTIF('📋 Task Tracker'!G4:G203,"🟠 High") -> 11
B12: ⏸ On Hold | F12: =COUNTIF('📋 Task Tracker'!H4:H203,"⏸ On Hold") -> 1 | J12: 🟡 Medium | N12: =COUNTIF('📋 Task Tracker'!G4:G203,"🟡 Medium") -> 8
B13: ✅ Completed | F13: =COUNTIF('📋 Task Tracker'!H4:H203,"✅ Completed") -> 20 | J13: 🟢 Low | N13: =COUNTIF('📋 Task Tracker'!G4:G203,"🟢 Low") -> 3
B14: ❌ Cancelled | F14: =COUNTIF('📋 Task Tracker'!H4:H203,"❌ Cancelled") -> 0
B17: 📅 Term-by-Term Breakdown (Annual View)
B18: Term | D18: Total Tasks | F18: Completed | H18: In Progress | J18: Pending | L18: Total Cost (AED) | N18: Completion %
B19: 🟣 Term 1 | D19: =COUNTIF('📋 Task Tracker'!F4:F203,"Term 1") -> 12 | F19: =COUNTIFS('📋 Task Tracker'!F4:F203,"Term 1",'📋 Task Tracker'!H4:H203,"✅ Completed") -> 12 | H19: =COUNTIFS('📋 Task Tracker'!F4:F203,"Term 1",'📋 Task Tracker'!H4:H203,"🔄 In Progress") -> 0 | J19: =COUNTIFS('📋 Task Tracker'!F4:F203,"Term 1",'📋 Task Tracker'!H4:H203,"⏳ Pending") -> 0 | L19: =SUMIF('📋 Task Tracker'!F4:F203,"Term 1",'📋 Task Tracker'!P4:P203) -> 20200 | N19: =IFERROR(COUNTIFS('📋 Task Tracker'!F4:F203,"Term 1",'📋 Task Tracker'!H4:H203,"✅ Completed")/COUNTIF('📋 Task Tracker'!F4:F203,"Term 1"),0) -> 1
B20: 🔵 Term 2 | D20: =COUNTIF('📋 Task Tracker'!F4:F203,"Term 2") -> 8 | F20: =COUNTIFS('📋 Task Tracker'!F4:F203,"Term 2",'📋 Task Tracker'!H4:H203,"✅ Completed") -> 8 | H20: =COUNTIFS('📋 Task Tracker'!F4:F203,"Term 2",'📋 Task Tracker'!H4:H203,"🔄 In Progress") -> 0 | J20: =COUNTIFS('📋 Task Tracker'!F4:F203,"Term 2",'📋 Task Tracker'!H4:H203,"⏳ Pending") -> 0 | L20: =SUMIF('📋 Task Tracker'!F4:F203,"Term 2",'📋 Task Tracker'!P4:P203) -> 18500 | N20: =IFERROR(COUNTIFS('📋 Task Tracker'!F4:F203,"Term 2",'📋 Task Tracker'!H4:H203,"✅ Completed")/COUNTIF('📋 Task Tracker'!F4:F203,"Term 2"),0) -> 1
B21: 🟡 Term 3 | D21: =COUNTIF('📋 Task Tracker'!F4:F203,"Term 3") -> 10 | F21: =COUNTIFS('📋 Task Tracker'!F4:F203,"Term 3",'📋 Task Tracker'!H4:H203,"✅ Completed") -> 0 | H21: =COUNTIFS('📋 Task Tracker'!F4:F203,"Term 3",'📋 Task Tracker'!H4:H203,"🔄 In Progress") -> 3 | J21: =COUNTIFS('📋 Task Tracker'!F4:F203,"Term 3",'📋 Task Tracker'!H4:H203,"⏳ Pending") -> 6 | L21: =SUMIF('📋 Task Tracker'!F4:F203,"Term 3",'📋 Task Tracker'!P4:P203) -> 23050 | N21: =IFERROR(COUNTIFS('📋 Task Tracker'!F4:F203,"Term 3",'📋 Task Tracker'!H4:H203,"✅ Completed")/COUNTIF('📋 Task Tracker'!F4:F203,"Term 3"),0) -> 0
B22: 🟢 Summer | D22: =COUNTIF('📋 Task Tracker'!F4:F203,"Summer") -> 0 | F22: =COUNTIFS('📋 Task Tracker'!F4:F203,"Summer",'📋 Task Tracker'!H4:H203,"✅ Completed") -> 0 | H22: =COUNTIFS('📋 Task Tracker'!F4:F203,"Summer",'📋 Task Tracker'!H4:H203,"🔄 In Progress") -> 0 | J22: =COUNTIFS('📋 Task Tracker'!F4:F203,"Summer",'📋 Task Tracker'!H4:H203,"⏳ Pending") -> 0 | L22: =SUMIF('📋 Task Tracker'!F4:F203,"Summer",'📋 Task Tracker'!P4:P203) -> 0 | N22: =IFERROR(COUNTIFS('📋 Task Tracker'!F4:F203,"Summer",'📋 Task Tracker'!H4:H203,"✅ Completed")/COUNTIF('📋 Task Tracker'!F4:F203,"Summer"),0) -> 0
B25: 📈 Annual Performance Metrics | J25: 💰 Annual Cost Analytics
B26: Annual Completion Rate | E26: =IFERROR(COUNTIF('📋 Task Tracker'!H4:H203,"✅ Completed")/COUNTA('📋 Task Tracker'!C4:C203),0) -> 0.66666667 | G26: Target: 75% | J26: Annual Total Cost | N26: =SUM('📋 Task Tracker'!P4:P203) -> 61750
B27: Annual On-Time Rate | E27: =IFERROR(COUNTIFS('📋 Task Tracker'!H4:H203,"✅ Completed",'📋 Task Tracker'!O4:O203,"<>🚨 OVERDUE")/COUNTIF('📋 Task Tracker'!H4:H203,"✅ Completed"),0) -> 1 | G27: Target: 85% | J27: Completed Tasks Cost | N27: =SUMIF('📋 Task Tracker'!H4:H203,"✅ Completed",'📋 Task Tracker'!P4:P203) -> 38700
B28: Avg. Health Score | E28: =IFERROR(AVERAGEIF('📋 Task Tracker'!H4:H203,"<>",'📋 Task Tracker'!S4:S203),0) -> 81.333333 | G28: / 100 | J28: Pending + In Progress | N28: =SUMIF('📋 Task Tracker'!H4:H203,"⏳ Pending",'📋 Task Tracker'!P4:P203)+SUMIF('📋 Task Tracker'!H4:H203,"🔄 In Progress",'📋 Task Tracker'!P4:P203) -> 22600
B29: Avg. Days to Close | E29: =IFERROR(AVERAGEIF('📋 Task Tracker'!M4:M203,"<>",'📋 Task Tracker'!N4:N203),0) -> 106.5 | G29: days avg. | J29: On-Hold Cost | N29: =SUMIF('📋 Task Tracker'!H4:H203,"⏸ On Hold",'📋 Task Tracker'!P4:P203) -> 450
B30: Annual Overdue Rate | E30: =IFERROR(COUNTIF('📋 Task Tracker'!O4:O203,"🚨 OVERDUE")/COUNTA('📋 Task Tracker'!C4:C203),0) -> 0 | G30: Target: <10% | J30: Critical Tasks Total | N30: =SUMIF('📋 Task Tracker'!G4:G203,"🔴 Critical",'📋 Task Tracker'!P4:P203) -> 20400
B33: 🗂️ Annual Analysis by Category
B34: Category | D34: Total | E34: Completed | F34: Pending | G34: In Progress | H34: On Hold | I34: Total Cost
B35: Electrical | D35: =COUNTIF('📋 Task Tracker'!D4:D203,"Electrical") -> 5 | E35: =COUNTIFS('📋 Task Tracker'!D4:D203,"Electrical",'📋 Task Tracker'!H4:H203,"✅ Completed") -> 3 | F35: =COUNTIFS('📋 Task Tracker'!D4:D203,"Electrical",'📋 Task Tracker'!H4:H203,"⏳ Pending") -> 1 | G35: =COUNTIFS('📋 Task Tracker'!D4:D203,"Electrical",'📋 Task Tracker'!H4:H203,"🔄 In Progress") -> 0 | H35: =COUNTIFS('📋 Task Tracker'!D4:D203,"Electrical",'📋 Task Tracker'!H4:H203,"⏸ On Hold") -> 1 | I35: =SUMIF('📋 Task Tracker'!D4:D203,"Electrical",'📋 Task Tracker'!P4:P203) -> 9200
B36: Plumbing | D36: =COUNTIF('📋 Task Tracker'!D4:D203,"Plumbing") -> 3 | E36: =COUNTIFS('📋 Task Tracker'!D4:D203,"Plumbing",'📋 Task Tracker'!H4:H203,"✅ Completed") -> 3 | F36: =COUNTIFS('📋 Task Tracker'!D4:D203,"Plumbing",'📋 Task Tracker'!H4:H203,"⏳ Pending") -> 0 | G36: =COUNTIFS('📋 Task Tracker'!D4:D203,"Plumbing",'📋 Task Tracker'!H4:H203,"🔄 In Progress") -> 0 | H36: =COUNTIFS('📋 Task Tracker'!D4:D203,"Plumbing",'📋 Task Tracker'!H4:H203,"⏸ On Hold") -> 0 | I36: =SUMIF('📋 Task Tracker'!D4:D203,"Plumbing",'📋 Task Tracker'!P4:P203) -> 3700
B37: Civil / Building | D37: =COUNTIF('📋 Task Tracker'!D4:D203,"Civil / Building") -> 5 | E37: =COUNTIFS('📋 Task Tracker'!D4:D203,"Civil / Building",'📋 Task Tracker'!H4:H203,"✅ Completed") -> 3 | F37: =COUNTIFS('📋 Task Tracker'!D4:D203,"Civil / Building",'📋 Task Tracker'!H4:H203,"⏳ Pending") -> 1 | G37: =COUNTIFS('📋 Task Tracker'!D4:D203,"Civil / Building",'📋 Task Tracker'!H4:H203,"🔄 In Progress") -> 1 | H37: =COUNTIFS('📋 Task Tracker'!D4:D203,"Civil / Building",'📋 Task Tracker'!H4:H203,"⏸ On Hold") -> 0 | I37: =SUMIF('📋 Task Tracker'!D4:D203,"Civil / Building",'📋 Task Tracker'!P4:P203) -> 13650
B38: HVAC / AC | D38: =COUNTIF('📋 Task Tracker'!D4:D203,"HVAC / AC") -> 5 | E38: =COUNTIFS('📋 Task Tracker'!D4:D203,"HVAC / AC",'📋 Task Tracker'!H4:H203,"✅ Completed") -> 3 | F38: =COUNTIFS('📋 Task Tracker'!D4:D203,"HVAC / AC",'📋 Task Tracker'!H4:H203,"⏳ Pending") -> 1 | G38: =COUNTIFS('📋 Task Tracker'!D4:D203,"HVAC / AC",'📋 Task Tracker'!H4:H203,"🔄 In Progress") -> 1 | H38: =COUNTIFS('📋 Task Tracker'!D4:D203,"HVAC / AC",'📋 Task Tracker'!H4:H203,"⏸ On Hold") -> 0 | I38: =SUMIF('📋 Task Tracker'!D4:D203,"HVAC / AC",'📋 Task Tracker'!P4:P203) -> 6150
B39: Painting | D39: =COUNTIF('📋 Task Tracker'!D4:D203,"Painting") -> 4 | E39: =COUNTIFS('📋 Task Tracker'!D4:D203,"Painting",'📋 Task Tracker'!H4:H203,"✅ Completed") -> 2 | F39: =COUNTIFS('📋 Task Tracker'!D4:D203,"Painting",'📋 Task Tracker'!H4:H203,"⏳ Pending") -> 2 | G39: =COUNTIFS('📋 Task Tracker'!D4:D203,"Painting",'📋 Task Tracker'!H4:H203,"🔄 In Progress") -> 0 | H39: =COUNTIFS('📋 Task Tracker'!D4:D203,"Painting",'📋 Task Tracker'!H4:H203,"⏸ On Hold") -> 0 | I39: =SUMIF('📋 Task Tracker'!D4:D203,"Painting",'📋 Task Tracker'!P4:P203) -> 9900
B40: Carpentry | D40: =COUNTIF('📋 Task Tracker'!D4:D203,"Carpentry") -> 2 | E40: =COUNTIFS('📋 Task Tracker'!D4:D203,"Carpentry",'📋 Task Tracker'!H4:H203,"✅ Completed") -> 2 | F40: =COUNTIFS('📋 Task Tracker'!D4:D203,"Carpentry",'📋 Task Tracker'!H4:H203,"⏳ Pending") -> 0 | G40: =COUNTIFS('📋 Task Tracker'!D4:D203,"Carpentry",'📋 Task Tracker'!H4:H203,"🔄 In Progress") -> 0 | H40: =COUNTIFS('📋 Task Tracker'!D4:D203,"Carpentry",'📋 Task Tracker'!H4:H203,"⏸ On Hold") -> 0 | I40: =SUMIF('📋 Task Tracker'!D4:D203,"Carpentry",'📋 Task Tracker'!P4:P203) -> 3450
B41: Cleaning | D41: =COUNTIF('📋 Task Tracker'!D4:D203,"Cleaning") -> 0 | E41: =COUNTIFS('📋 Task Tracker'!D4:D203,"Cleaning",'📋 Task Tracker'!H4:H203,"✅ Completed") -> 0 | F41: =COUNTIFS('📋 Task Tracker'!D4:D203,"Cleaning",'📋 Task Tracker'!H4:H203,"⏳ Pending") -> 0 | G41: =COUNTIFS('📋 Task Tracker'!D4:D203,"Cleaning",'📋 Task Tracker'!H4:H203,"🔄 In Progress") -> 0 | H41: =COUNTIFS('📋 Task Tracker'!D4:D203,"Cleaning",'📋 Task Tracker'!H4:H203,"⏸ On Hold") -> 0 | I41: =SUMIF('📋 Task Tracker'!D4:D203,"Cleaning",'📋 Task Tracker'!P4:P203) -> 0
B42: IT / AV Equipment | D42: =COUNTIF('📋 Task Tracker'!D4:D203,"IT / AV Equipment") -> 1 | E42: =COUNTIFS('📋 Task Tracker'!D4:D203,"IT / AV Equipment",'📋 Task Tracker'!H4:H203,"✅ Completed") -> 1 | F42: =COUNTIFS('📋 Task Tracker'!D4:D203,"IT / AV Equipment",'📋 Task Tracker'!H4:H203,"⏳ Pending") -> 0 | G42: =COUNTIFS('📋 Task Tracker'!D4:D203,"IT / AV Equipment",'📋 Task Tracker'!H4:H203,"🔄 In Progress") -> 0 | H42: =COUNTIFS('📋 Task Tracker'!D4:D203,"IT / AV Equipment",'📋 Task Tracker'!H4:H203,"⏸ On Hold") -> 0 | I42: =SUMIF('📋 Task Tracker'!D4:D203,"IT / AV Equipment",'📋 Task Tracker'!P4:P203) -> 5800
B43: Safety & Security | D43: =COUNTIF('📋 Task Tracker'!D4:D203,"Safety & Security") -> 3 | E43: =COUNTIFS('📋 Task Tracker'!D4:D203,"Safety & Security",'📋 Task Tracker'!H4:H203,"✅ Completed") -> 2 | F43: =COUNTIFS('📋 Task Tracker'!D4:D203,"Safety & Security",'📋 Task Tracker'!H4:H203,"⏳ Pending") -> 0 | G43: =COUNTIFS('📋 Task Tracker'!D4:D203,"Safety & Security",'📋 Task Tracker'!H4:H203,"🔄 In Progress") -> 1 | H43: =COUNTIFS('📋 Task Tracker'!D4:D203,"Safety & Security",'📋 Task Tracker'!H4:H203,"⏸ On Hold") -> 0 | I43: =SUMIF('📋 Task Tracker'!D4:D203,"Safety & Security",'📋 Task Tracker'!P4:P203) -> 8700
B44: Landscaping | D44: =COUNTIF('📋 Task Tracker'!D4:D203,"Landscaping") -> 0 | E44: =COUNTIFS('📋 Task Tracker'!D4:D203,"Landscaping",'📋 Task Tracker'!H4:H203,"✅ Completed") -> 0 | F44: =COUNTIFS('📋 Task Tracker'!D4:D203,"Landscaping",'📋 Task Tracker'!H4:H203,"⏳ Pending") -> 0 | G44: =COUNTIFS('📋 Task Tracker'!D4:D203,"Landscaping",'📋 Task Tracker'!H4:H203,"🔄 In Progress") -> 0 | H44: =COUNTIFS('📋 Task Tracker'!D4:D203,"Landscaping",'📋 Task Tracker'!H4:H203,"⏸ On Hold") -> 0 | I44: =SUMIF('📋 Task Tracker'!D4:D203,"Landscaping",'📋 Task Tracker'!P4:P203) -> 0
B45: Furniture | D45: =COUNTIF('📋 Task Tracker'!D4:D203,"Furniture") -> 0 | E45: =COUNTIFS('📋 Task Tracker'!D4:D203,"Furniture",'📋 Task Tracker'!H4:H203,"✅ Completed") -> 0 | F45: =COUNTIFS('📋 Task Tracker'!D4:D203,"Furniture",'📋 Task Tracker'!H4:H203,"⏳ Pending") -> 0 | G45: =COUNTIFS('📋 Task Tracker'!D4:D203,"Furniture",'📋 Task Tracker'!H4:H203,"🔄 In Progress") -> 0 | H45: =COUNTIFS('📋 Task Tracker'!D4:D203,"Furniture",'📋 Task Tracker'!H4:H203,"⏸ On Hold") -> 0 | I45: =SUMIF('📋 Task Tracker'!D4:D203,"Furniture",'📋 Task Tracker'!P4:P203) -> 0
B46: Pest Control | D46: =COUNTIF('📋 Task Tracker'!D4:D203,"Pest Control") -> 2 | E46: =COUNTIFS('📋 Task Tracker'!D4:D203,"Pest Control",'📋 Task Tracker'!H4:H203,"✅ Completed") -> 1 | F46: =COUNTIFS('📋 Task Tracker'!D4:D203,"Pest Control",'📋 Task Tracker'!H4:H203,"⏳ Pending") -> 1 | G46: =COUNTIFS('📋 Task Tracker'!D4:D203,"Pest Control",'📋 Task Tracker'!H4:H203,"🔄 In Progress") -> 0 | H46: =COUNTIFS('📋 Task Tracker'!D4:D203,"Pest Control",'📋 Task Tracker'!H4:H203,"⏸ On Hold") -> 0 | I46: =SUMIF('📋 Task Tracker'!D4:D203,"Pest Control",'📋 Task Tracker'!P4:P203) -> 1200
B47: Other | D47: =COUNTIF('📋 Task Tracker'!D4:D203,"Other") -> 0 | E47: =COUNTIFS('📋 Task Tracker'!D4:D203,"Other",'📋 Task Tracker'!H4:H203,"✅ Completed") -> 0 | F47: =COUNTIFS('📋 Task Tracker'!D4:D203,"Other",'📋 Task Tracker'!H4:H203,"⏳ Pending") -> 0 | G47: =COUNTIFS('📋 Task Tracker'!D4:D203,"Other",'📋 Task Tracker'!H4:H203,"🔄 In Progress") -> 0 | H47: =COUNTIFS('📋 Task Tracker'!D4:D203,"Other",'📋 Task Tracker'!H4:H203,"⏸ On Hold") -> 0 | I47: =SUMIF('📋 Task Tracker'!D4:D203,"Other",'📋 Task Tracker'!P4:P203) -> 0
B50: 🤖 Smart Alerts & System Recommendations (Auto-Updated)
B51: =IF(COUNTIF('📋 Task Tracker'!O4:O203,"🚨 OVERDUE")>0,"🚨 OVERDUE: "&COUNTIF('📋 Task Tracker'!O4:O203,"🚨 OVERDUE")&" task(s) exceeded their due date — immediate action required.","✅ No overdue tasks. All deadlines met.") -> ✅ No overdue tasks. All deadlines met.
B52: =IF(COUNTIFS('📋 Task Tracker'!G4:G203,"🔴 Critical",'📋 Task Tracker'!H4:H203,"⏳ Pending")>0,"⚠️ CRITICAL: "&COUNTIFS('📋 Task Tracker'!G4:G203,"🔴 Critical",'📋 Task Tracker'!H4:H203,"⏳ Pending")&" Critical-priority tasks still Pending — do not delay.","✅ No critical tasks pending.") -> ⚠️ CRITICAL: 2 Critical-priority tasks still Pending — do not delay.
...

Sheet 🏢 Vendors
A1: 🏢 APPROVED VENDORS & CONTRACTORS — ARAB UNITY SCHOOL | AY 2025-26
A2: # | B2: Vendor Name | C2: Specialty | D2: Contact Name | E2: Phone | F2: Email | G2: Contract Expires | H2: Rating | I2: Notes
A3: 1 | B3: Al Noor Contractors | C3: Civil/Building | D3: Mohammed Al Noor | E3: +971 50 123 4567 | F3: info@alnoor.ae | G3: 31/12/2026 | H3: ⭐⭐⭐⭐ | I3: Preferred civil works
A4: 2 | B4: Cool Air Services | C4: HVAC/AC | D4: Rajesh Kumar | E4: +971 55 234 5678 | F4: service@coolair.ae | G4: 30/06/2026 | H4: ⭐⭐⭐⭐⭐ | I4: Priority HVAC vendor
A5: 3 | B5: Spark Electric Co. | C5: Electrical | D5: Ali Hassan | E5: +971 52 345 6789 | F5: ali@sparkco.ae | G5: 31/12/2026 | H5: ⭐⭐⭐⭐ | I5: Approved for all electrical
A6: 4 | B6: BrightPaint LLC | C6: Painting | D6: James Wilson | E6: +971 56 456 7890 | F6: james@brightpaint.ae | G6: 31/08/2026 | H6: ⭐⭐⭐ | I6: Scheduled works only
A7: 5 | B7: TechVision UAE | C7: IT/AV Equipment | D7: Sara Al Mansoori | E7: +971 50 567 8901 | F7: sara@techvision.ae | G7: 30/09/2026 | H7: ⭐⭐⭐⭐⭐ | I7: IT procurement partner
A8: 6 | B8: SafeBuild Contractors | C8: Civil/Building | D8: Khalid Ibrahim | E8: +971 54 678 9012 | F8: khalid@safebuild.ae | G8: 28/02/2027 | H8: ⭐⭐⭐⭐ | I8: Outdoor & structural
A9: 7 | B9: SecureVision Systems | C9: Safety & Security | D9: Omar Al Rashid | E9: +971 55 789 0123 | F9: omar@securevision.ae | G9: 31/07/2026 | H9: ⭐⭐⭐⭐ | I9: CCTV & access control
A10: 8 | B10: PestFree UAE | C10: Pest Control | D10: Ramesh Patel | E10: +971 52 890 1234 | F10: info@pestfree.ae | G10: 31/03/2027 | H10: ⭐⭐⭐ | I10: Monthly treatment
A11: 9 | B11: In-House Maintenance | C11: General | D11: Maintenance Team | E11: Ext. 101 | F11: maintenance@aus.ae | G11: N/A | H11: ⭐⭐⭐⭐⭐ | I11: All routine tasks
A12: 10 | B12: PoolTech UAE | C12: Plumbing | D12: Hassan Al Ameri | E12: +971 56 901 2345 | F12: info@pooltech.ae | G12: 30/06/2026 | H12: ⭐⭐⭐⭐ | I12: Pool & plumbing specialist
A13: 11 | B13: FloorPro UAE | C13: Carpentry | D13: Robert Nair | E13: +971 52 012 3456 | F13: info@floorpro.ae | G13: 31/12/2026 | H13: ⭐⭐⭐ | I13: Flooring specialist
A14: 12 | B14: FireSafe Systems | C14: Safety & Security | D14: Ahmed Karimi | E14: +971 55 123 4567 | F14: service@firesafe.ae | G14: 31/03/2026 | H14: ⭐⭐⭐⭐⭐ | I14: Fire safety compliance
A15: 13
A16: 14
A17: 15
A18: 16
A19: 17
A20: 18
A21: 19
A22: 20
A23: 21
A24: 22
A25: 23
A26: 24
... A34: 32

Sheet 📅 Annual Schedule
A1: 📅 ANNUAL PREVENTIVE MAINTENANCE SCHEDULE — AY 2025-26
D2: 🟣 Term 1 (Sep–Dec) | H2: 🔵 Term 2 (Jan–Mar) | K2: 🟡 Term 3 (Apr–Jun) | N2: 🟢 Summer (Jul–Aug)
A3: # | B3: Recurring Task / Activity | C3: Responsible Team | D3: Sep | E3: Oct | F3: Nov | G3: Dec | H3: Jan | I3: Feb | J3: Mar | K3: Apr | L3: May | M3: Jun | N3: Jul | O3: Aug
A4: 1 | B4: Weekly building inspection | C4: Maintenance Team | D4: ⏳ | E4: ⏳ | F4: ⏳ | G4: ⏳ | H4: ⏳ | I4: ⏳ | J4: ⏳ | K4: ⏳ | L4: ⏳ | M4: ⏳ | N4: ⏳ | O4: ⏳
A5: 2 | B5: Toilets deep cleaning | C5: Cleaning Crew | D5: ⏳ | E5: ⏳ | F5: ⏳ | G5: ⏳ | H5: ⏳ | I5: ⏳ | J5: ⏳ | K5: ⏳ | L5: ⏳ | M5: ⏳ | N5: ⏳ | O5: ⏳
A6: 3 | B6: Fire extinguisher inspection | C6: Safety Officer | D6: ⏳ | G6: ⏳ | J6: ⏳ | M6: ⏳
A7: 4 | B7: Generator test run | C7: Electrical Team | D7: ⏳ | E7: ⏳ | F7: ⏳ | G7: ⏳ | H7: ⏳ | I7: ⏳ | J7: ⏳ | K7: ⏳ | L7: ⏳ | M7: ⏳ | N7: ⏳ | O7: ⏳
A8: 5 | B8: AC filter cleaning – all units | C8: HVAC Contractor | D8: ⏳ | F8: ⏳ | H8: ⏳ | J8: ⏳ | L8: ⏳ | N8: ⏳
A9: 6 | B9: CCTV system check | C9: IT Team | D9: ⏳ | G9: ⏳ | J9: ⏳ | M9: ⏳
A10: 7 | B10: Playground equipment inspection | C10: Maintenance Team | D10: ⏳ | F10: ⏳ | H10: ⏳ | J10: ⏳ | L10: ⏳ | N10: ⏳
A11: 8 | B11: Pool water treatment & testing | C11: Pool Contractor | D11: ⏳ | E11: ⏳ | F11: ⏳ | G11: ⏳ | H11: ⏳ | I11: ⏳ | J11: ⏳ | K11: ⏳ | L11: ⏳ | M11: ⏳ | N11: ⏳ | O11: ⏳
A12: 9 | B12: Pest control – canteen & kitchen | C12: PestFree UAE | D12: ⏳ | E12: ⏳ | F12: ⏳ | G12: ⏳ | H12: ⏳ | I12: ⏳ | J12: ⏳ | K12: ⏳ | L12: ⏳ | M12: ⏳ | N12: ⏳ | O12: ⏳
A13: 10 | B13: Corridor lighting check | C13: Electrical Team | D13: ⏳ | G13: ⏳ | J13: ⏳ | M13: ⏳
A14: 11 | B14: Library AC maintenance | C14: Cool Air Services | E14: ⏳ | H14: ⏳ | K14: ⏳ | N14: ⏳
A15: 12 | B15: Roof & drainage inspection | C15: Al Noor Contractors | D15: ⏳ | J15: ⏳
A16: 13 | B16: Sports hall floor check | C16: Maintenance Team | D16: ⏳ | H16: ⏳ | L16: ⏳
A17: 14 | B17: Canteen deep clean & inspection | C17: Cleaning Crew | D17: ⏳ | E17: ⏳ | F17: ⏳ | G17: ⏳ | H17: ⏳ | I17: ⏳ | J17: ⏳ | K17: ⏳ | L17: ⏳ | M17: ⏳ | N17: ⏳ | O17: ⏳
A18: 15 | B18: Emergency lighting test | C18: Electrical Team | D18: ⏳ | G18: ⏳ | J18: ⏳ | M18: ⏳
A19: 16 | B19: Water tanks cleaning | C19: Maintenance Team | D19: ⏳ | J19: ⏳
A20: 17 | B20: Annual fire drill | C20: Safety Officer | F20: ⏳ | M20: ⏳
A21: 18 | B21: Garden & landscaping maintenance | C21: Landscaping Team | D21: ⏳ | E21: ⏳ | F21: ⏳ | G21: ⏳ | H21: ⏳ | I21: ⏳ | J21: ⏳ | K21: ⏳ | L21: ⏳ | M21: ⏳ | N21: ⏳ | O21: ⏳
A23: 📊 Monthly Completion Summary (✅ Done count): | D23: =COUNTIF(D4:D21,"✅ Done") -> 0 | E23: =COUNTIF(E4:E21,"✅ Done") -> 0 | F23: =COUNTIF(F4:F21,"✅ Done") -> 0 | G23: =COUNTIF(G4:G21,"✅ Done") -> 0 | H23: =COUNTIF(H4:H21,"✅ Done") -> 0 | I23: =COUNTIF(I4:I21,"✅ Done") -> 0 | J23: =COUNTIF(J4:J21,"✅ Done") -> 0 | K23: =COUNTIF(K4:K21,"✅ Done") -> 0 | ... O23: =COUNTIF(O4:O21,"✅ Done") -> 0

Sheet 📈 Annual Trend Log
A1: 📈 ANNUAL KPI TREND LOG — ARAB UNITY SCHOOL | AY 2025-26
A2: Month | B2: Term | C2: Total Tasks | D2: Completed | E2: Pending | F2: In Progress | G2: Overdue | H2: Completion % | I2: On-Time % | J2: Avg Health | K2: Cost (AED) | L2: Budget Var. | M2: Tasks w/ Files | N2: Notes
A3: September | B3: Term 1 | C3: 45 | D3: 32 | E3: 6 | F3: 5 | G3: 2 | H3: 71.1% | I3: 88% | J3: 72 | K3: 38500 | M3: 8 | N3: Strong start
A4: October | B4: Term 1 | C4: 38 | D4: 28 | E4: 5 | F4: 3 | G4: 1 | H4: 73.7% | I4: 90% | J4: 75 | K4: 29200 | M4: 5
A5: November | B5: Term 1 | C5: 52 | D5: 40 | E5: 7 | F5: 4 | G5: 3 | H5: 76.9% | I5: 85% | J5: 78 | K5: 44100 | M5: 12 | N5: Increased civil works
A6: December | B6: Term 1 | C6: 29 | D6: 25 | E6: 2 | F6: 2 | G6: 0 | H6: 86.2% | I6: 93% | J6: 85 | K6: 21800 | M6: 4 | N6: Holiday — fewer tasks
A7: January | B7: Term 2 | C7: 41 | D7: 30 | E7: 6 | F7: 4 | G7: 2 | H7: 73.2% | I7: 87% | J7: 74 | K7: 33700 | M7: 7
A8: February | B8: Term 2 | C8: 48 | D8: 35 | E8: 8 | F8: 4 | G8: 3 | H8: 72.9% | I8: 84% | J8: 73 | K8: 42500 | M8: 9
A9: March | B9: Term 3 | N9: Current month
A10: April | B10: Term 3
A11: May | B11: Term 3
A12: June | B12: Term 3
A13: July | B13: Summer
A14: August | B14: Summer
A15: 📊 ANNUAL TOTALS | C15: =SUM(C3:C14) -> 253 | D15: =SUM(D3:D14) -> 190 | K15: =SUM(K3:K14) -> 209800

Sheet ℹ️ Guide
B1: ℹ️ HOW TO USE — AUS MAINTENANCE SYSTEM | AY 2025-26 (ANNUAL)
B3: 📋 Task Tracker (Annual)
B4: Central database for ALL maintenance tasks across the full academic year. ▸ Column F = Term (Term 1 / Term 2 / Term 3 / Summer) — colour-coded automatically ▸ Column N = Days to Close — auto-calculated from date reported to completion ▸ Column O = Overdue? — auto-flags 🚨 OVERDUE when due date passes ▸ Column S = Health Score (0–100) — auto-rated by status & priority ▸ Annual cost total is at the bottom of column P ▸ Row turns GREEN when Completed | RED tint for Critical tasks ▸ Supports up to 200 tasks for the full year
B6: 📎 File Attachment Column (Column U)
B7: Column U — '📎 Attachment / File Link' is for linking supporting documents: HOW TO ATTACH A FILE: Option 1 — Paste the file path: • Right-click the cell → insert a hyperlink • Or type the full file path: C:\Maintenance\Photos\MNT-001.jpg • Or a SharePoint / Teams URL: https://ausschool.sharepoint.com/... Option 2 — Insert Hyperlink (recommended): 1. Click the cell in column U 2. Press Ctrl + K 3. Choose 'Existing File or Web Page' 4. Browse to your photo, PDF, or document 5. Click OK — cell shows clickable link Supported file types: Photos (.jpg/.png), PDFs, Word docs, invoices, certificates Tip: Store files in a shared folder (SharePoint / Teams) so all team members can open links
B9: 📊 Analytics Dashboard (Annual)
B10: Full annual live analytics — auto-updates from Task Tracker. ▸ 7 Annual KPI cards ▸ Term-by-Term Breakdown: performance for each of 3 terms + summer ▸ Annual completion rate, on-time rate, avg health score, avg days to close ▸ Annual cost breakdown: total / completed / pending / critical ▸ Category & Location analysis ▸ 🤖 6 Smart Alerts — auto-flag issues as you work
B12: 📅 Annual Schedule
B13: Preventive maintenance calendar across all 12 months. ▸ Colour-coded by Term: 🟣 T1 (Sep–Dec) | 🔵 T2 (Jan–Mar) | 🟡 T3 (Apr–Jun) | 🟢 Summer ▸ ⏳ = Planned month for that task ▸ Click any ⏳ cell → dropdown: ✅ Done / 🔄 In Progress / ❌ Skip / ➡️ Rescheduled ▸ Summary row at the bottom counts completed tasks per month
B15: 📈 Annual Trend Log
B16: Month-by-month KPI history for the full academic year. ▸ Fill in each month at month-end review ▸ Column M = Tasks with Attachments (count tasks that have files linked) ▸ Annual totals row auto-sums at the bottom ▸ Completion % column has green/red colour coding ▸ Use for DSIB evidence, board reports, annual review
B18: ⚙️ Settings
... B22: ▸ Save after every session — share via SharePoint or Teams ▸ Use Ctrl+F to search any task or vendor ▸ Sort Task Tracker by Due Date or Priority for daily planning ▸ Add file links (Ctrl+K) immediately after task is logged ▸ Update Trend Log at the end of each month ▸ Print Analytics Dashboard (landscape A3) for management meetings ▸ Archive completed tasks at end of each term to keep tracker clean
